<?xml version="1.0"?>
<robot name="mobile_robot" xmlns:xacro="http://ros.org/wiki/xacro">

  <!-- Define robot constants -->
  <xacro:property name="width" value="0.3"/>
  <xacro:property name="length" value="0.5"/>
  <xacro:property name="height" value="0.1"/>
  <xacro:arg name="robot_color" default="Gazebo/Blue"/> <!-- allow spawning with custom colors (e.g., Gazebo/Green for leader) -->
  <xacro:property name="wheel_radius" value="0.06"/>
  <xacro:property name="wheel_width" value="0.03"/>
  <xacro:property name="wheel_separation" value="0.35"/>
  <xacro:property name="wheel_base" value="0.3"/> <!-- Distance between front and rear axle -->

  <!-- Base Link -->
  <link name="base_link">
    <visual>
      <geometry>
        <box size="${length} ${width} ${height}"/>
      </geometry>
      <material name="blue">
        <color rgba="0 0 1 1"/>
      </material>
    </visual>
    <collision>
      <geometry>
        <box size="${length} ${width} ${height}"/>
      </geometry>
    </collision>
    <inertial>
      <mass value="2.0"/>
      <inertia ixx="0.02" ixy="0.0" ixz="0.0" iyy="0.02" iyz="0.0" izz="0.02"/>
    </inertial>
  </link>

  <!-- Wheel Macro -->
  <xacro:macro name="wheel" params="prefix x_reflect y_reflect">
    <link name="${prefix}_wheel">
      <visual>
        <geometry>
          <cylinder radius="${wheel_radius}" length="${wheel_width}"/>
        </geometry>
        <material name="black">
          <color rgba="0 0 0 1"/>
        </material>
      </visual>
      <collision>
        <geometry>
          <cylinder radius="${wheel_radius}" length="${wheel_width}"/>
        </geometry>
      </collision>
      <inertial>
        <mass value="0.5"/>
        <inertia ixx="0.001" ixy="0.0" ixz="0.0" iyy="0.001" iyz="0.0" izz="0.001"/>
      </inertial>
    </link>

    <joint name="${prefix}_wheel_joint" type="continuous">
      <parent link="base_link"/>
      <child link="${prefix}_wheel"/>
      <origin xyz="${x_reflect * wheel_base/2} ${y_reflect * wheel_separation/2} -${height/2}" rpy="-1.5707 0 0"/>
      <axis xyz="0 0 1"/>
    </joint>

    <gazebo reference="${prefix}_wheel">
      <material>Gazebo/Black</material>
    </gazebo>
  </xacro:macro>

  <!-- Instantiate 4 Wheels -->
  <xacro:wheel prefix="front_left" x_reflect="1" y_reflect="1"/>
  <xacro:wheel prefix="front_right" x_reflect="1" y_reflect="-1"/>
  <xacro:wheel prefix="rear_left" x_reflect="-1" y_reflect="1"/>
  <xacro:wheel prefix="rear_right" x_reflect="-1" y_reflect="-1"/>

  <!-- Base Link Material -->
  <gazebo reference="base_link">
    <material>$(arg robot_color)</material>
  </gazebo>

  <!-- Add Camera Sensor for Follower Drones -->
  <link name="camera_link">
    <visual>
      <geometry>
        <box size="0.05 0.05 0.05"/>
      </geometry>
      <material name="black"/>
    </visual>
  </link>

  <joint name="camera_joint" type="fixed">
    <parent link="base_link"/>
    <child link="camera_link"/>
    <origin xyz="${length/2 + 0.025} 0 0" rpy="0 0 0"/> <!-- at the exact front center -->
  </joint>

  <!-- Camera Plugin -->
  <gazebo reference="camera_link">
    <sensor type="camera" name="camera">
      <update_rate>30.0</update_rate>
      <camera>
        <horizontal_fov>1.3962634</horizontal_fov>
        <image>
          <width>640</width>
          <height>480</height>
          <format>R8G8B8</format>
        </image>
        <clip>
          <near>0.02</near>
          <far>300</far>
        </clip>
      </camera>
      <plugin name="camera_controller" filename="libgazebo_ros_camera.so">
        <alwaysOn>true</alwaysOn>
        <updateRate>30.0</updateRate>
        <cameraName>camera</cameraName>
        <imageTopicName>image_raw</imageTopicName>
        <cameraInfoTopicName>camera_info</cameraInfoTopicName>
        <frameName>camera_link</frameName>
      </plugin>
    </sensor>
  </gazebo>

  <!-- Skid Steer Drive Plugin -->
  <gazebo>
    <plugin name="diff_drive" filename="libgazebo_ros_diff_drive.so">
      <ros>
        <namespace>/</namespace>
      </ros>
      <update_rate>100.0</update_rate>
      <num_wheel_pairs>2</num_wheel_pairs>
      
      <!-- wheels -->
      <left_joint>front_left_wheel_joint</left_joint>
      <left_joint>rear_left_wheel_joint</left_joint>
      <right_joint>front_right_wheel_joint</right_joint>
      <right_joint>rear_right_wheel_joint</right_joint>

      <wheel_separation>${wheel_separation}</wheel_separation>
      <wheel_diameter>${wheel_radius * 2}</wheel_diameter>
      <max_wheel_torque>20</max_wheel_torque>
      <max_wheel_acceleration>1.0</max_wheel_acceleration>

      <command_topic>cmd_vel</command_topic>
      <odometry_topic>odom</odometry_topic>
      <odometry_frame>odom</odometry_frame>
      <robot_base_frame>base_link</robot_base_frame>

      <publish_odom>true</publish_odom>
      <publish_odom_tf>true</publish_odom_tf>
      <publish_wheel_tf>true</publish_wheel_tf>
    </plugin>
  </gazebo>

</robot>
